<?xml version="1.0"?>
<sdf version="1.4">
  <model name="gripper">
    <static>false</static>
    <link name="link_axis_x">
      <pose>0 0 0 0 0 0</pose>
    </link>
    <link name="link_axis_y">
      <pose>0 0 0 0 0 0</pose>
    </link>

    <joint name="axis_x" type="prismatic">
      <child>link_axis_y</child>
      <parent>link_axis_x</parent>
      <pose>0 0 0 0 0 0</pose>
      <axis>
        <limit>
          <lower>-0.2</lower>
          <upper>0.2</upper>
        </limit>
        <xyz>1 0 0</xyz>
      </axis>
    </joint>
    <joint name="axis_y" type="prismatic">
      <child>link</child>
      <parent>link_axis_y</parent>
      <pose>0 0 0 0 0 0</pose>
      <axis>
        <limit>
          <lower>-0.3</lower>
          <upper>0.2</upper>
        </limit>
        <xyz>0 1 0</xyz>
      </axis>
    </joint>

    <link name="link">
      <pose>0 0 0 0 0 0</pose>
      <!-- Origin is where the puck should be gripped -->
      <visual name="back-visual">
        <pose>-0.15 0 0 0 0 0</pose>
        <geometry>
          <box>
            <size>0.005 0.15 0.1</size>
          </box>
        </geometry>
        <material>
          <script>
            <uri>model://logistics_league_field/materials/scripts/</uri>
            <uri>model://logistics_league_field/materials/textures/</uri>
            <name>Logistics_League_Field/Image</name>
          </script>
        </material>
        <cast_shadows>false</cast_shadows>
      </visual>
      <visual name="left-servo-visual">
        <pose>-0.12 0.04 0 0 0 0</pose>
        <geometry>
          <box>
            <size>0.06 0.03 0.04</size>
          </box>
        </geometry>
        <material>
          <ambient>0.0 0.0 0.0 0.1</ambient>
          <diffuse>0.0 0.0 0.0 0.11</diffuse>
        </material>
        <cast_shadows>false</cast_shadows>
      </visual>
      <visual name="right-servo-visual">
        <pose>-0.12 -0.04 0 0 0 0</pose>
        <geometry>
          <box>
            <size>0.06 0.03 0.04</size>
          </box>
        </geometry>
        <material>
          <ambient>0.0 0.0 0.0 0.1</ambient>
          <diffuse>0.0 0.0 0.0 0.11</diffuse>
        </material>
        <cast_shadows>false</cast_shadows>
      </visual>
      <visual name="left-finger-visual">
        <pose>-0.04 -0.04 0 0 0 0</pose>
        <geometry>
          <box>
            <size>0.1 0.01 0.02</size>
          </box>
        </geometry>
        <material>
          <ambient>0.7 0.6 0.0 0.8</ambient>
          <diffuse>0.7 0.6 0.0 0.8</diffuse>
        </material>
        <cast_shadows>false</cast_shadows>
      </visual>
      <visual name="right-finger-visual">
        <pose>-0.04 0.04 0 0 0 0</pose>
        <geometry>
          <box>
            <size>0.1 0.01 0.02</size>
          </box>
        </geometry>
        <material>
          <ambient>0.7 0.6 0.0 0.8</ambient>
          <diffuse>0.7 0.6 0.0 0.8</diffuse>
        </material>
        <cast_shadows>false</cast_shadows>
      </visual>
    </link>
    <plugin name="Gripper" filename="libgripper.so" />
  </model>
</sdf>